Workbook

Sheet Loan_Data
A1: Customer_ID | B1: Customer_Name | C1: Father_Name | D1: Gender | E1: Age | F1: Marital_Status | G1: Occupation | H1: Education_Level | I1: Monthly_Income | J1: Employment_Type | K1: Years_of_Employment | L1: District | M1: Division | N1: Residential_Status | O1: Number_of_Dependents | P1: Branch_ID | Q1: Branch_Name | R1: Branch_City | S1: Branch_Division | T1: Loan_ID | U1: Loan_Type | V1: Loan_Amount | W1: Interest_Rate | X1: Loan_Term_Months | Y1: Application_Date | Z1: Approval_Date | AA1: Disbursement_Date | AB1: EMI_Amount | AC1: Collateral_Value | AD1: Existing_Loan_Count | AE1: Account_Balance | AF1: Savings_Amount | AG1: Monthly_Transaction_Count | AH1: Average_Monthly_Deposit | AI1: Credit_Score | AJ1: Debt_to_Income_Ratio | AK1: Risk_Level | AL1: Late_Payment_Count | AM1: Previous_Default | AN1: Repayment_Status | AO1: Loan_Status | AP1: Default_Probability
A2: BPBL-CUS-000001 | B2: Asaduzzaman Patwary | C2: Forhad Ahmed | D2: Male | E2: 43 | F2: Single | G2: Engineer | H2: Bachelor's | I2: 99000 | J2: Private | K2: 19 | L2: Feni | M2: Chattogram | N2: Own House | O2: 1 | P2: BR-11 | Q2: BPBL Kandirpar Branch | R2: Cumilla | S2: Chattogram | T2: BPBL-LN-2026-000001 | U2: Home Loan | V2: 4174000 | W2: 11.26 | X2: 258 | Y2: 46174 | Z2: 46183 | AA2: 46187 | AB2: =ROUND(PMT(W2/1200,X2,-V2),2) -> 43032.51 | AC2: 4617000 | AD2: 0 | AE2: 154900 | AF2: 56100 | AG2: 21 | AH2: 63900 | AI2: 759 | AJ2: =ROUND(AB2/I2,4) -> 0.4347 | AK2: =IF(AND(AI2>=750,AJ2<=0.35),"Low",IF(AND(AI2>=600,AJ2<=0.5),"Medium","High")) -> Medium | AL2: 1 | AM2: No | AN2: On Time | AO2: Approved | AP2: 0.165
A3: BPBL-CUS-000002 | B3: Aktar Akand | C3: Imran Gazi | D3: Male | E3: 46 | F3: Married | G3: Teacher | H3: Bachelor's | I3: 29500 | J3: Private | K3: 24 | L3: Kushtia | M3: Khulna | N3: Own House | O3: 0 | P3: BR-13 | Q3: BPBL M.K. Road Branch | R3: Jessore | S3: Khulna | T3: BPBL-LN-2026-000002 | U3: Business Loan | V3: 300000 | W3: 14.18 | X3: 54 | Y3: 46199 | Z3: 46207 | AA3: 46212 | AB3: =ROUND(PMT(W3/1200,X3,-V3),2) -> 7546.97 | AC3: 307000 | AD3: 0 | AE3: 21500 | AF3: 12400 | AG3: 33 | AH3: 31600 | AI3: 656 | AJ3: =ROUND(AB3/I3,4) -> 0.2558 | AK3: =IF(AND(AI3>=750,AJ3<=0.35),"Low",IF(AND(AI3>=600,AJ3<=0.5),"Medium","High")) -> Medium | AL3: 1 | AM3: No | AN3: On Time | AO3: Approved | AP3: 0.232
A4: BPBL-CUS-000003 | B4: Rezaul Patwary | C4: Riaz Rahman | D4: Male | E4: 31 | F4: Single | G4: Government Service | H4: HSC | I4: 47500 | J4: Government | K4: 9 | L4: Habiganj | M4: Sylhet | N4: Family Owned | O4: 0 | P4: BR-05 | Q4: BPBL Zindabazar Branch | R4: Sylhet | S4: Sylhet | T4: BPBL-LN-2026-000003 | U4: Agricultural Loan | V4: 116000 | W4: 10.2 | X4: 12 | Y4: 46188 | Z4: 46194 | AA4: 46196 | AB4: =ROUND(PMT(W4/1200,X4,-V4),2) -> 10209.04 | AC4: 0 | AD4: 1 | AF4: 41100 | AG4: 43 | AH4: 21300 | AI4: 710 | AJ4: =ROUND(AB4/I4,4) -> 0.2149 | AK4: =IF(AND(AI4>=750,AJ4<=0.35),"Low",IF(AND(AI4>=600,AJ4<=0.5),"Medium","High")) -> Medium | AM4: No | AN4: On Time | AO4: Closed | AP4: 0.164
A5: BPBL-CUS-000004 | B5: Bashir Das | C5: Monir Mondol | D5: Male | E5: 46 | F5: Married | G5: Retired | H5: HSC | I5: 28000 | J5: Retired | K5: 23 | L5: Tangail | M5: Dhaka | N5: Own House | O5: 0 | P5: BR-10 | Q5: BPBL Chashara Branch | R5: Narayanganj | S5: Dhaka | T5: BPBL-LN-2026-000004 | U5: Personal Loan | V5: 206000 | W5: 15.6 | X5: 30 | Y5: 46182 | Z5: 46192 | AA5: 46198 | AB5: =ROUND(PMT(W5/1200,X5,-V5),2) -> 8336.46 | AC5: 0 | AD5: 0 | AE5: 27800 | AG5: 3 | AH5: 10100 | AI5: 719 | AJ5: =ROUND(AB5/I5,4) -> 0.2977 | AK5: =IF(AND(AI5>=750,AJ5<=0.35),"Low",IF(AND(AI5>=600,AJ5<=0.5),"Medium","High")) -> Medium | AL5: 1 | AM5: No | AN5: On Time | AO5: Approved | AP5: 0.234
A6: BPBL-CUS-000005 | B6: Touhidul Sikder | C6: Mamunur Rahman | D6: Male | E6: 44 | F6: Married | G6: Engineer | H6: Master's | I6: 166500 | J6: Private | K6: 20 | L6: Khulna | M6: Khulna | N6: Staff Quarters | O6: 2 | P6: BR-03 | Q6: BPBL Sonadanga Branch | R6: Khulna | S6: Khulna | T6: BPBL-LN-2026-000005 | U6: Personal Loan | V6: 1500000 | W6: 13.27 | X6: 24 | Y6: 46198 | Z6: 46200 | AA6: 46202 | AB6: =ROUND(PMT(W6/1200,X6,-V6),2) -> 71503.11 | AC6: 0 | AD6: 0 | AE6: 600300 | AF6: 201800 | AG6: 46 | AH6: 65900 | AI6: 615 | AJ6: =ROUND(AB6/I6,4) -> 0.4294 | AK6: =IF(AND(AI6>=750,AJ6<=0.35),"Low",IF(AND(AI6>=600,AJ6<=0.5),"Medium","High")) -> Medium | AL6: 0 | AM6: No | AN6: On Time | AO6: Approved | AP6: 0.334
A7: BPBL-CUS-000006 | B7: Ferdousi Khan | C7: Wahidul Sardar | D7: Female | E7: 48 | F7: Single | G7: Housewife | H7: Below SSC | I7: 15000 | J7: Unemployed | K7: 20 | L7: Nilphamari | M7: Rangpur | N7: Family Owned | O7: 0 | P7: BR-07 | Q7: BPBL Jahaj Company Mor Branch | R7: Rangpur | S7: Rangpur | T7: BPBL-LN-2026-000006 | U7: Education Loan | V7: 100000 | W7: 8.41 | X7: 12 | Y7: 46179 | Z7: 46184 | AA7: 46189 | AB7: =ROUND(PMT(W7/1200,X7,-V7),2) -> 8717.81 | AC7: 0 | AD7: 1 | AE7: 34200 | AF7: 18900 | AG7: 42 | AH7: 7500 | AI7: 467 | AJ7: =ROUND(AB7/I7,4) -> 0.5812 | AK7: =IF(AND(AI7>=750,AJ7<=0.35),"Low",IF(AND(AI7>=600,AJ7<=0.5),"Medium","High")) -> High | AL7: 0 | AM7: No | AN7: Delayed | AO7: Approved | AP7: 0.38
A8: BPBL-CUS-000007 | B8: Aminul Islam | C8: Aminul Faruqui | D8: Male | E8: 54 | F8: Married | G8: Retired | H8: SSC | I8: 20000 | J8: Retired | K8: 28 | L8: Narayanganj | M8: Dhaka | O8: 1 | P8: BR-14 | Q8: BPBL Victoria Road Branch | R8: Tangail | S8: Dhaka | T8: BPBL-LN-2026-000007 | U8: Agricultural Loan | V8: 195000 | W8: 10.01 | X8: 24 | Y8: 46200 | AB8: =ROUND(PMT(W8/1200,X8,-V8),2) -> 8999.16 | AC8: 0 | AD8: 0 | AE8: 26000 | AF8: 8200 | AH8: 19100 | AI8: 769 | AJ8: =ROUND(AB8/I8,4) -> 0.45 | AK8: =IF(AND(AI8>=750,AJ8<=0.35),"Low",IF(AND(AI8>=600,AJ8<=0.5),"Medium","High")) -> Medium | AL8: 2 | AM8: No | AO8: Rejected | AP8: 0.161
A9: BPBL-CUS-000008 | B9: Anika Mia | C9: Masud Sardar | D9: Female | E9: 21 | F9: Married | G9: Housewife | H9: Bachelor's | I9: 19000 | J9: Unemployed | K9: 0 | L9: Cumilla | M9: Chattogram | N9: Own House | O9: 1 | P9: BR-02 | Q9: BPBL Agrabad Branch | R9: Chattogram | S9: Chattogram | T9: BPBL-LN-2026-000008 | U9: Business Loan | V9: 359000 | W9: 16.38 | X9: 84 | Y9: 46180 | AB9: =ROUND(PMT(W9/1200,X9,-V9),2) -> 7208.4 | AC9: 404000 | AD9: 0 | AE9: 28400 | AF9: 3400 | AG9: 27 | AH9: 15000 | AI9: 691 | AJ9: =ROUND(AB9/I9,4) -> 0.3794 | AK9: =IF(AND(AI9>=750,AJ9<=0.35),"Low",IF(AND(AI9>=600,AJ9<=0.5),"Medium","High")) -> Medium | AL9: 2 | AM9: No | AO9: Pending | AP9: 0.183
A10: BPBL-CUS-000009 | B10: Shirin Patwary | C10: Nurul Das | D10: Female | E10: 30 | F10: Married | G10: Government Service | H10: HSC | I10: 33000 | J10: Government | K10: 3 | L10: Pirojpur | M10: Barishal | N10: Rented House | O10: 2 | P10: BR-07 | Q10: BPBL Jahaj Company Mor Branch | R10: Rangpur | S10: Rangpur | T10: BPBL-LN-2026-000009 | U10: Personal Loan | V10: 389000 | W10: 14.78 | X10: 48 | Y10: 46175 | Z10: 46176 | AA10: 46179 | AB10: =ROUND(PMT(W10/1200,X10,-V10),2) -> 10782.83 | AC10: 0 | AD10: 0 | AE10: 59000 | AF10: 24600 | AG10: 15 | AH10: 26600 | AI10: 734 | AJ10: =ROUND(AB10/I10,4) -> 0.3268 | AK10: =IF(AND(AI10>=750,AJ10<=0.35),"Low",IF(AND(AI10>=600,AJ10<=0.5),"Medium","High")) -> Medium | AL10: 0 | AM10: No | AN10: On Time | AO10: Approved | AP10: 0.224
A11: BPBL-CUS-000010 | B11: Ashraf Khan | C11: Aminul Mia | D11: Male | E11: 28 | F11: Married | G11: Self-Employed | H11: Below SSC | I11: 23500 | J11: Self-Employed | K11: 6 | L11: Chapainawabganj | M11: Rajshahi | N11: Own House | O11: 2 | P11: BR-04 | Q11: BPBL Shaheb Bazar Branch | R11: Rajshahi | S11: Rajshahi | T11: BPBL-LN-2026-000010 | U11: Education Loan | V11: 254000 | W11: 8.63 | X11: 30 | Y11: 46175 | Z11: 46177 | AA11: 46178 | AB11: =ROUND(PMT(W11/1200,X11,-V11),2) -> 9443.12 | AC11: 0 | AD11: 0 | AE11: 68600 | AF11: 20100 | AG11: 34 | AH11: 24700 | AI11: 861 | AJ11: =ROUND(AB11/I11,4) -> 0.4018 | AK11: =IF(AND(AI11>=750,AJ11<=0.35),"Low",IF(AND(AI11>=600,AJ11<=0.5),"Medium","High")) -> Medium | AL11: 0 | AM11: No | AN11: On Time | AO11: Closed | AP11: 0.033
A12: BPBL-CUS-000011 | B12: Tariqul Sheikh | C12: Mizanur Miah | D12: Male | E12: 33 | F12: Married | G12: Freelancer | I12: 23000 | J12: Self-Employed | K12: 8 | L12: Rajshahi | M12: Rajshahi | N12: Own House | O12: 0 | P12: BR-04 | Q12: BPBL Shaheb Bazar Branch | R12: Rajshahi | S12: Rajshahi | T12: BPBL-LN-2026-000011 | U12: Agricultural Loan | V12: 51000 | W12: 8.01 | X12: 6 | Y12: 46176 | AB12: =ROUND(PMT(W12/1200,X12,-V12),2) -> 8699.68 | AC12: 0 | AD12: 2 | AE12: 39600 | AF12: 18300 | AG12: 44 | AH12: 23400 | AI12: 786 | AJ12: =ROUND(AB12/I12,4) -> 0.3782 | AK12: =IF(AND(AI12>=750,AJ12<=0.35),"Low",IF(AND(AI12>=600,AJ12<=0.5),"Medium","High")) -> Medium | AM12: No | AO12: Pending | AP12: 0.101
A13: BPBL-CUS-000012 | B13: Habibur Mia | C13: Delwar Talukder | D13: Male | E13: 40 | F13: Married | G13: Self-Employed | I13: 54500 | J13: Self-Employed | K13: 15 | L13: Mymensingh | M13: Mymensingh | N13: Rented House | O13: 1 | P13: BR-08 | Q13: BPBL Notun Bazar Branch | R13: Mymensingh | S13: Mymensingh | T13: BPBL-LN-2026-000012 | U13: Business Loan | V13: 1026000 | W13: 11.87 | X13: 60 | Y13: 46195 | AB13: =ROUND(PMT(W13/1200,X13,-V13),2) -> 22755.46 | AC13: 1029000 | AD13: 0 | AE13: 159200 | AF13: 67800 | AG13: 10 | AH13: 26100 | AI13: 753 | AJ13: =ROUND(AB13/I13,4) -> 0.4175 | AK13: =IF(AND(AI13>=750,AJ13<=0.35),"Low",IF(AND(AI13>=600,AJ13<=0.5),"Medium","High")) -> Medium | AL13: 0 | AM13: No | AO13: Rejected | AP13: 0.182
A14: BPBL-CUS-000013 | B14: Yeasin Faruqui | C14: Aminul Hossain | D14: Male | E14: 68 | F14: Married | G14: Doctor | H14: PhD | I14: 239500 | J14: Self-Employed | K14: 7 | L14: Munshiganj | M14: Dhaka | N14: Staff Quarters | O14: 2 | P14: BR-01 | Q14: BPBL Gulshan Branch | R14: Dhaka | S14: Dhaka | T14: BPBL-LN-2026-000013 | U14: Personal Loan | V14: 1500000 | W14: 12.7 | X14: 60 | Y14: 46193 | Z14: 46197 | AA14: 46201 | AB14: =ROUND(PMT(W14/1200,X14,-V14),2) -> 33899.69 | AC14: 0 | AD14: 2 | AE14: 648800 | AF14: 322700 | AG14: 24 | AH14: 168200 | AI14: 707 | AJ14: =ROUND(AB14/I14,4) -> 0.1415 | AK14: =IF(AND(AI14>=750,AJ14<=0.35),"Low",IF(AND(AI14>=600,AJ14<=0.5),"Medium","High")) -> Medium | AL14: 0 | AM14: No | AN14: On Time | AO14: Approved | AP14: 0.252
A15: BPBL-CUS-000014 | B15: Iqbal Khan | C15: Mahmudul Hawlader | D15: Male | E15: 35 | F15: Widowed | G15: Business Owner | H15: Bachelor's | I15: 182000 | J15: Business | K15: 11 | L15: Kishoreganj | M15: Dhaka | N15: Own House | O15: 0 | P15: BR-10 | Q15: BPBL Chashara Branch | R15: Narayanganj | S15: Dhaka | T15: BPBL-LN-2026-000014 | U15: Car Loan | V15: 2788000 | W15: 13.11 | X15: 72 | Y15: 46188 | Z15: 46190 | AA15: 46191 | AB15: =ROUND(PMT(W15/1200,X15,-V15),2) -> 56128.6 | AC15: 4063000 | AD15: 1 | AE15: 706800 | AF15: 411200 | AG15: 38 | AH15: 178800 | AI15: 759 | AJ15: =ROUND(AB15/I15,4) -> 0.3084 | AK15: =IF(AND(AI15>=750,AJ15<=0.35),"Low",IF(AND(AI15>=600,AJ15<=0.5),"Medium","High")) -> Low | AL15: 0 | AM15: No | AN15: On Time | AO15: Approved | AP15: 0.164
A16: BPBL-CUS-000015 | B16: Shafin Gazi | C16: Mostafa Khan | D16: Male | E16: 28 | F16: Married | G16: Business Owner | H16: HSC | I16: 37000 | J16: Business | K16: 5 | L16: Rajshahi | M16: Rajshahi | N16: Family Owned | O16: 2 | P16: BR-04 | Q16: BPBL Shaheb Bazar Branch | R16: Rajshahi | S16: Rajshahi | T16: BPBL-LN-2026-000015 | U16: Business Loan | V16: 654000 | W16: 14.35 | X16: 72 | Y16: 46199 | AB16: =ROUND(PMT(W16/1200,X16,-V16),2) -> 13599.03 | AC16: 896000 | AD16: 2 | AE16: 65100 | AG16: 42 | AH16: 35100 | AI16: 596 | AJ16: =ROUND(AB16/I16,4) -> 0.3675 | AK16: =IF(AND(AI16>=750,AJ16<=0.35),"Low",IF(AND(AI16>=600,AJ16<=0.5),"Medium","High")) -> High | AL16: 2 | AM16: No | AO16: Rejected | AP16: 0.391
A17: BPBL-CUS-000016 | B17: Shafiqul Patwary | C17: Mehedi Ahmed | D17: Male | E17: 41 | F17: Married | G17: Business Owner | H17: Bachelor's | I17: 94500 | J17: Business | K17: 18 | L17: Noakhali | M17: Chattogram | N17: Own House | O17: 3 | P17: BR-15 | Q17: BPBL Maijdee Court Branch | R17: Noakhali | S17: Chattogram | T17: BPBL-LN-2026-000016 | U17: SME Loan | V17: 534000 | W17: 11.88 | X17: 18 | Y17: 46189 | Z17: 46190 | AA17: 46191 | AB17: =ROUND(PMT(W17/1200,X17,-V17),2) -> 32534.65 | AC17: 688000 | AD17: 1 | AE17: 226700 | AF17: 55100 | AG17: 20 | AI17: 750 | AJ17: =ROUND(AB17/I17,4) -> 0.3443 | AK17: =IF(AND(AI17>=750,AJ17<=0.35),"Low",IF(AND(AI17>=600,AJ17<=0.5),"Medium","High")) -> Low | AL17: 0 | AM17: No | AN17: On Time | AO17: Approved | AP17: 0.176
A18: BPBL-CUS-000017 | B18: Shamim Karim | C18: Mehedi Sardar | D18: Male | E18: 32 | H18: PhD | I18: 287000 | J18: Self-Employed | K18: 14 | L18: Patuakhali | M18: Barishal | N18: Own House | O18: 0 | P18: BR-06 | Q18: BPBL Sadar Road Branch | R18: Barishal | S18: Barishal | T18: BPBL-LN-2026-000017 | U18: Agricultural Loan | V18: 800000 | W18: 7.38 | X18: 24 | Y18: 46191 | Z18: 46197 | AA18: 46202 | AB18: =ROUND(PMT(W18/1200,X18,-V18),2) -> 35956.04 | AC18: 0 | AD18: 1 | AE18: 872900 | AF18: 513200 | AG18: 36 | AH18: 204600 | AI18: 811 | AJ18: =ROUND(AB18/I18,4) -> 0.1253 | AK18: =IF(AND(AI18>=750,AJ18<=0.35),"Low",IF(AND(AI18>=600,AJ18<=0.5),"Medium","High")) -> Low | AL18: 0 | AM18: No | AN18: On Time | AO18: Approved | AP18: 0.207
A19: BPBL-CUS-000018 | B19: Yeasin Miah | C19: Tanvir Sarkar | D19: Male | E19: 49 | F19: Married | G19: Government Service | H19: Master's | I19: 55000 | J19: Government | K19: 24 | L19: Munshiganj | M19: Dhaka | O19: 1 | P19: BR-06 | Q19: BPBL Sadar Road Branch | R19: Barishal | S19: Barishal | T19: BPBL-LN-2026-000018 | U19: Home Loan | V19: 1566000 | W19: 8.8 | X19: 96 | Y19: 46199 | AB19: =ROUND(PMT(W19/1200,X19,-V19),2) -> 22780.07 | AC19: 1762000 | AD19: 0 | AE19: 154600 | AF19: 37100 | AG19: 33 | AH19: 58500 | AI19: 786 | AJ19: =ROUND(AB19/I19,4) -> 0.4142 | AK19: =IF(AND(AI19>=750,AJ19<=0.35),"Low",IF(AND(AI19>=600,AJ19<=0.5),"Medium","High")) -> Medium | AL19: 0 | AM19: No | AO19: Rejected | AP19: 0.215
A20: BPBL-CUS-000019 | B20: Nazrul Mollah | C20: Tanvir Mia | D20: Male | E20: 42 | F20: Single | G20: Private Service | H20: HSC | I20: 73500 | J20: Private | K20: 16 | L20: Lalmonirhat | M20: Rangpur | N20: Own House | O20: 0 | P20: BR-12 | Q20: BPBL Satmatha Branch | R20: Bogura | S20: Rajshahi | T20: BPBL-LN-2026-000019 | U20: Agricultural Loan | V20: 85000 | W20: 7.92 | X20: 6 | Y20: 46200 | AB20: =ROUND(PMT(W20/1200,X20,-V20),2) -> 14495.71 | AC20: 0 | AD20: 0 | AE20: 61900 | AF20: 21400 | AG20: 54 | AH20: 49900 | AI20: 670 | AJ20: =ROUND(AB20/I20,4) -> 0.1972 | AK20: =IF(AND(AI20>=750,AJ20<=0.35),"Low",IF(AND(AI20>=600,AJ20<=0.5),"Medium","High")) -> Medium | AL20: 1 | AM20: No | AO20: Rejected | AP20: 0.256
A21: BPBL-CUS-000020 | B21: Touhidul Pramanik | C21: Shamim Roy | D21: Male | E21: 35 | G21: Doctor | H21: PhD | I21: 139000 | J21: Self-Employed | K21: 12 | L21: Nilphamari | M21: Rangpur | N21: Own House | O21: 2 | P21: BR-07 | Q21: BPBL Jahaj Company Mor Branch | R21: Rangpur | S21: Rangpur | T21: BPBL-LN-2026-000020 | U21: Agricultural Loan | V21: 449000 | W21: 9.66 | X21: 24 | Y21: 46182 | Z21: 46192 | AA21: 46196 | AB21: =ROUND(PMT(W21/1200,X21,-V21),2) -> 20648.68 | AC21: 0 | AD21: 0 | AE21: 354500 | AF21: 202100 | AG21: 28 | AH21: 105700 | AI21: 862 | AJ21: =ROUND(AB21/I21,4) -> 0.1486 | AK21: =IF(AND(AI21>=750,AJ21<=0.35),"Low",IF(AND(AI21>=600,AJ21<=0.5),"Medium","High")) -> Low | AL21: 0 | AM21: No | AN21: On Time | AO21: Approved | AP21: 0.067
A22: BPBL-CUS-000021 | B22: Hossain Sardar | C22: Nurul Miah | D22: Male | E22: 55 | F22: Married | G22: Doctor | H22: PhD | I22: 171000 | J22: Self-Employed | K22: 32 | L22: Cox's Bazar | M22: Chattogram | N22: Rented House | O22: 3 | P22: BR-02 | Q22: BPBL Agrabad Branch | R22: Chattogram | S22: Chattogram | T22: BPBL-LN-2026-000021 | U22: Agricultural Loan | V22: 699000 | W22: 9.99 | X22: 12 | Y22: 46193 | Z22: 46195 | AA22: 46201 | AB22: =ROUND(PMT(W22/1200,X22,-V22),2) -> 61449.95 | AC22: 0 | AD22: 2 | AE22: 461900 | AF22: 248800 | AG22: 18 | AH22: 151900 | AI22: 681 | AJ22: =ROUND(AB22/I22,4) -> 0.3594 | AK22: =IF(AND(AI22>=750,AJ22<=0.35),"Low",IF(AND(AI22>=600,AJ22<=0.5),"Medium","High")) -> Medium | AL22: 2 | AM22: No | AN22: Delayed | AO22: Approved | AP22: 0.284
A23: BPBL-CUS-000022 | B23: Nayeem Majumder | C23: Towhid Talukder | D23: Male | E23: 31 | F23: Married | G23: Retired | H23: HSC | I23: 28000 | J23: Retired | K23: 6 | L23: Barishal | M23: Barishal | N23: Rented House | O23: 0 | P23: BR-06 | Q23: BPBL Sadar Road Branch | R23: Barishal | S23: Barishal | T23: BPBL-LN-2026-000022 | U23: Personal Loan | V23: 269000 | W23: 15.88 | X23: 54 | Y23: 46187 | Z23: 46197 | AA23: 46203 | AB23: =ROUND(PMT(W23/1200,X23,-V23),2) -> 7003.1 | AC23: 0 | AD23: 3 | AE23: 87900 | AF23: 13300 | AG23: 21 | AH23: 28600 | AI23: 811 | AJ23: =ROUND(AB23/I23,4) -> 0.2501 | AK23: =IF(AND(AI23>=750,AJ23<=0.35),"Low",IF(AND(AI23>=600,AJ23<=0.5),"Medium","High")) -> Low | AL23: 0 | AM23: No | AN23: On Time | AO23: Closed | AP23: 0.184
A24: BPBL-CUS-000023 | B24: Shapla Rahman | C24: Ataur Miah | D24: Female | E24: 52 | F24: Married | G24: Engineer | H24: Bachelor's | I24: 116000 | J24: Private | K24: 29 | L24: Narayanganj | M24: Dhaka | N24: Own House | O24: 2 | P24: BR-09 | Q24: BPBL Chandona Chowrasta Branch | R24: Gazipur | S24: Dhaka | T24: BPBL-LN-2026-000023 | U24: Home Loan | V24: 3767000 | W24: 9.31 | X24: 222 | Y24: 46181 | AB24: =ROUND(PMT(W24/1200,X24,-V24),2) -> 35633.95 | AC24: 5184000 | AD24: 0 | AE24: 95000 | AF24: 33000 | AG24: 36 | AH24: 40100 | AI24: 771 | AJ24: =ROUND(AB24/I24,4) -> 0.3072 | AK24: =IF(AND(AI24>=750,AJ24<=0.35),"Low",IF(AND(AI24>=600,AJ24<=0.5),"Medium","High")) -> Low | AL24: 4 | AM24: Yes | AO24: Pending | AP24: 0.34
A25: BPBL-CUS-000024 | B25: Borsha Mondol | C25: Nurul Sarker | D25: Female | E25: 21 | F25: Married | G25: Engineer | H25: Bachelor's | I25: 137000 | J25: Private | K25: 0 | L25: Noakhali | M25: Chattogram | N25: Own House | O25: 2 | P25: BR-15 | Q25: BPBL Maijdee Court Branch | R25: Noakhali | S25: Chattogram | T25: BPBL-LN-2026-000024 | U25: SME Loan | V25: 2981000 | W25: 10.63 | X25: 60 | Y25: 46188 | Z25: 46192 | AA25: 46193 | AB25: =ROUND(PMT(W25/1200,X25,-V25),2) -> 64265.46 | AC25: 3089000 | AD25: 0 | AE25: 107500 | AF25: 15300 | AG25: 40 | AH25: 149200 | AI25: 782 | AJ25: =ROUND(AB25/I25,4) -> 0.4691 | AK25: =IF(AND(AI25>=750,AJ25<=0.35),"Low",IF(AND(AI25>=600,AJ25<=0.5),"Medium","High")) -> Medium | AL25: 0 | AM25: No | AN25: On Time | AO25: Approved | AP25: 0.171
A26: BPBL-CUS-000025 | B26: Rokeya Sarker | C26: Hasan Sheikh | D26: Female | E26: 22 | F26: Single | G26: Freelancer | H26: Master's | I26: 27500 | J26: Self-Employed | K26: 0 | L26: Faridpur | M26: Dhaka | N26: Rented House | O26: 3 | P26: BR-09 | Q26: BPBL Chandona Chowrasta Branch | R26: Gazipur | S26: Dhaka | T26: BPBL-LN-2026-000025 | U26: Education Loan | V26: 607000 | W26: 8.02 | X26: 48 | Y26: 46181 | AB26: =ROUND(PMT(W26/1200,X26,-V26),2) -> 14824.34 | AC26: 0 | AE26: 85600 | AF26: 33500 | AG26: 16 | AH26: 29400 | AI26: 504 | AJ26: =ROUND(AB26/I26,4) -> 0.5391 | AK26: =IF(AND(AI26>=750,AJ26<=0.35),"Low",IF(AND(AI26>=600,AJ26<=0.5),"Medium","High")) -> High | AL26: 2 | AM26: No | AO26: Rejected | AP26: 0.444
A27: BPBL-CUS-000026 | B27: Rezaul Miah | C27: Zahirul Hasan | D27: Male | E27: 22 | F27: Married | G27: Farmer | I27: 8500 | J27: Self-Employed | K27: 1 | L27: Moulvibazar | M27: Sylhet | N27: Own House | O27: 1 | P27: BR-05 | Q27: BPBL Zindabazar Branch | R27: Sylhet | S27: Sylhet | T27: BPBL-LN-2026-000026 | U27: Education Loan | V27: 233000 | W27: 9.2 | X27: 84 | Y27: 46187 | Z27: 46196 | AA27: 46200 | AB27: =ROUND(PMT(W27/1200,X27,-V27),2) -> 3772.45 | AC27: 0 | AD27: 1 | AE27: 24900 | AF27: 8100 | AG27: 33 | AH27: 6800 | AI27: 686 | AJ27: =ROUND(AB27/I27,4) -> 0.4438 | AK27: =IF(AND(AI27>=750,AJ27<=0.35),"Low",IF(AND(AI27>=600,AJ27<=0.5),"Medium","High")) -> Medium | AM27: No | AN27: On Time | AO27: Approved | AP27: 0.341
A28: BPBL-CUS-000027 | B28: Ataur Karim | C28: Jasim Hawlader | D28: Male | E28: 47 | F28: Married | G28: Engineer | H28: Master's | I28: 134500 | J28: Private | K28: 20 | L28: Gaibandha | M28: Rangpur | N28: Rented House | O28: 0 | P28: BR-14 | Q28: BPBL Victoria Road Branch | R28: Tangail | S28: Dhaka | T28: BPBL-LN-2026-000027 | U28: Home Loan | V28: 2774000 | W28: 8.56 | X28: 168 | Y28: 46186 | Z28: 46193 | AA28: 46199 | AB28: =ROUND(PMT(W28/1200,X28,-V28),2) -> 28388.53 | AC28: 3264000 | AD28: 0 | AF28: 311900 | AG28: 30 | AH28: 115500 | AI28: 900 | AJ28: =ROUND(AB28/I28,4) -> 0.2111 | AK28: =IF(AND(AI28>=750,AJ28<=0.35),"Low",IF(AND(AI28>=600,AJ28<=0.5),"Medium","High")) -> Low | AL28: 0 | AM28: No | AN28: On Time | AO28: Approved | AP28: 0.01
A29: BPBL-CUS-000028 | B29: Liton Hasan | C29: Quamrul Hawlader | D29: Male | E29: 21 | F29: Single | G29: Private Service | H29: Bachelor's | I29: 51500 | J29: Private | K29: 0 | L29: Dhaka | M29: Dhaka | N29: Own House | O29: 1 | P29: BR-01 | Q29: BPBL Gulshan Branch | R29: Dhaka | S29: Dhaka | T29: BPBL-LN-2026-000028 | U29: Car Loan | V29: 887000 | W29: 9.9 | X29: 36 | Y29: 46186 | Z29: 46193 | AA29: 46196 | AB29: =ROUND(PMT(W29/1200,X29,-V29),2) -> 28579.37 | AC29: 1246000 | AD29: 0 | AE29: 200600 | AF29: 104500 | AG29: 46 | AH29: 50000 | AI29: 581 | AJ29: =ROUND(AB29/I29,4) -> 0.5549 | AK29: =IF(AND(AI29>=750,AJ29<=0.35),"Low",IF(AND(AI29>=600,AJ29<=0.5),"Medium","High")) -> High | AL29: 2 | AM29: No | AN29: Missed Payment | AO29: Approved | AP29: 0.292
A30: BPBL-CUS-000029 | B30: Promi Munshi | C30: Mizanur Chowdhury | D30: Female | E30: 21 | F30: Single | G30: Engineer | H30: Bachelor's | I30: 61500 | J30: Private | K30: 0 | L30: Bhola | M30: Barishal | N30: Rented House | O30: 0 | P30: BR-01 | Q30: BPBL Gulshan Branch | R30: Dhaka | S30: Dhaka | T30: BPBL-LN-2026-000029 | U30: Car Loan | V30: 368000 | W30: 11.25 | X30: 18 | Y30: 46177 | Z30: 46181 | AA30: 46185 | AB30: =ROUND(PMT(W30/1200,X30,-V30),2) -> 22313.4 | AC30: 544000 | AD30: 0 | AE30: 175300 | AF30: 71700 | AG30: 35 | AH30: 36100 | AI30: 721 | AJ30: =ROUND(AB30/I30,4) -> 0.3628 | AK30: =IF(AND(AI30>=750,AJ30<=0.35),"Low",IF(AND(AI30>=600,AJ30<=0.5),"Medium","High")) -> Medium | AL30: 6 | AM30: No | AN30: Delayed | AO30: Approved | AP30: 0.235
A31: BPBL-CUS-000030 | B31: Kamal Faruqui | C31: Touhidul Hossain | D31: Male | E31: 41 | F31: Widowed | G31: Engineer | H31: Master's | I31: 97000 | J31: Private | K31: 16 | L31: Jessore | M31: Khulna | N31: Own House | O31: 0 | P31: BR-13 | Q31: BPBL M.K. Road Branch | R31: Jessore | S31: Khulna | T31: BPBL-LN-2026-000030 | U31: SME Loan | V31: 499000 | W31: 10.95 | X31: 12 | Y31: 46177 | Z31: 46182 | AA31: 46188 | AB31: =ROUND(PMT(W31/1200,X31,-V31),2) -> 44090.81 | AC31: 687000 | AD31: 1 | AE31: 120800 | AF31: 20300 | AG31: 40 | AH31: 30200 | AI31: 736 | AJ31: =ROUND(AB31/I31,4) -> 0.4545 | AK31: =IF(AND(AI31>=750,AJ31<=0.35),"Low",IF(AND(AI31>=600,AJ31<=0.5),"Medium","High")) -> Medium | AL31: 2 | AM31: No | AN31: On Time | AO31: Closed | AP31: 0.278
A32: BPBL-CUS-000031 | B32: Bashir Patwary | C32: Jasim Hawlader | D32: Male | E32: 49 | F32: Married | G32: Freelancer | H32: Bachelor's | I32: 28500 | J32: Self-Employed | K32: 27 | L32: Barishal | M32: Barishal | N32: Staff Quarters | O32: 1 | P32: BR-06 | Q32: BPBL Sadar Road Branch | R32: Barishal | S32: Barishal | T32: BPBL-LN-2026-000031 | U32: SME Loan | V32: 452000 | W32: 12.6 | X32: 72 | Y32: 46196 | Z32: 46199 | AA32: 46205 | AB32: =ROUND(PMT(W32/1200,X32,-V32),2) -> 8978.35 | AC32: 667000 | AD32: 1 | AE32: 60000 | AF32: 35400 | AG32: 27 | AH32: 19800 | AI32: 857 | AJ32: =ROUND(AB32/I32,4) -> 0.315 | AK32: =IF(AND(AI32>=750,AJ32<=0.35),"Low",IF(AND(AI32>=600,AJ32<=0.5),"Medium","High")) -> Low | AL32: 0 | AM32: No | AN32: On Time | AO32: Approved | AP32: 0.011
A33: BPBL-CUS-000032 | B33: Sohel Bhuiyan | C33: Ashraf Patwary | D33: Male | E33: 50 | F33: Married | G33: Retired | H33: Bachelor's | I33: 22500 | J33: Retired | K33: 24 | L33: Jhenaidah | M33: Khulna | N33: Family Owned | O33: 1 | P33: BR-13 | Q33: BPBL M.K. Road Branch | R33: Jessore | S33: Khulna | T33: BPBL-LN-2026-000032 | U33: Business Loan | V33: 300000 | W33: 13.08 | X33: 78 | Y33: 46184 | Z33: 46190 | AA33: 46192 | AB33: =ROUND(PMT(W33/1200,X33,-V33),2) -> 5729.8 | AC33: 371000 | AD33: 0 | AE33: 26400 | AF33: 3200 | AG33: 35 | AH33: 9800 | AI33: 759 | AJ33: =ROUND(AB33/I33,4) -> 0.2547 | AK33: =IF(AND(AI33>=750,AJ33<=0.35),"Low",IF(AND(AI33>=600,AJ33<=0.5),"Medium","High")) -> Low | AL33: 0 | AM33: No | AN33: On Time | AO33: Approved | AP33: 0.13
A34: BPBL-CUS-000033 | B34: Monir Sheikh | C34: Mostafa Munshi | D34: Male | E34: 29 | F34: Widowed | G34: Private Service | H34: Master's | I34: 49000 | J34: Private | K34: 2 | L34: Khagrachari | M34: Chattogram | N34: Rented House | O34: 0 | P34: BR-15 | Q34: BPBL Maijdee Court Branch | R34: Noakhali | S34: Chattogram | T34: BPBL-LN-2026-000033 | U34: Car Loan | V34: 609000 | W34: 13.02 | X34: 48 | Y34: 46196 | Z34: 46197 | AA34: 46198 | AB34: =ROUND(PMT(W34/1200,X34,-V34),2) -> 16343.99 | AC34: 634000 | AD34: 0 | AE34: 162800 | AF34: 77200 | AG34: 24 | AH34: 21900 | AI34: 571 | AJ34: =ROUND(AB34/I34,4) -> 0.3336 | AK34: =IF(AND(AI34>=750,AJ34<=0.35),"Low",IF(AND(AI34>=600,AJ34<=0.5),"Medium","High")) -> High | AL34: 3 | AM34: No | AN34: On Time | AO34: Approved | AP34: 0.38
A35: BPBL-CUS-000034 | B35: Sathi Sarkar | C35: Anisur Talukder | D35: Female | E35: 31 | F35: Married | G35: Farmer | H35: SSC | I35: 10500 | J35: Self-Employed | K35: 8 | L35: Mymensingh | M35: Mymensingh | N35: Own House | O35: 2 | P35: BR-08 | Q35: BPBL Notun Bazar Branch | R35: Mymensingh | S35: Mymensingh | T35: BPBL-LN-2026-000034 | U35: Car Loan | V35: 300000 | W35: 9.73 | X35: 36 | Y35: 46191 | AB35: =ROUND(PMT(W35/1200,X35,-V35),2) -> 9642.17 | AC35: 380000 | AD35: 0 | AE35: 19100 | AF35: 2100 | AG35: 15 | AH35: 5900 | AI35: 780 | AJ35: =ROUND(AB35/I35,4) -> 0.9183 | AK35: =IF(AND(AI35>=750,AJ35<=0.35),"Low",IF(AND(AI35>=600,AJ35<=0.5),"Medium","High")) -> High | AL35: 2 | AM35: No | AO35: Pending | AP35: 0.146
A36: BPBL-CUS-000035 | B36: Eti Das | C36: Arif Ahmed | D36: Female | E36: 30 | F36: Single | G36: Self-Employed | H36: HSC | I36: 26500 | J36: Self-Employed | K36: 11 | L36: Natore | M36: Rajshahi | N36: Own House | O36: 0 | P36: BR-12 | Q36: BPBL Satmatha Branch | R36: Bogura | S36: Rajshahi | T36: BPBL-LN-2026-000035 | U36: Agricultural Loan | V36: 288000 | W36: 9.14 | X36: 24 | Y36: 46196 | AB36: =ROUND(PMT(W36/1200,X36,-V36),2) -> 13175.71 | AC36: 0 | AD36: 2 | AE36: 25100 | AG36: 50 | AH36: 15600 | AI36: 690 | AJ36: =ROUND(AB36/I36,4) -> 0.4972 | AK36: =IF(AND(AI36>=750,AJ36<=0.35),"Low",IF(AND(AI36>=600,AJ36<=0.5),"Medium","High")) -> Medium | AL36: 0 | AM36: No | AO36: Pending | AP36: 0.215
A37: BPBL-CUS-000036 | B37: Aminul Chowdhury | C37: Golam Miah | D37: Male | E37: 48 | F37: Married | H37: Master's | I37: 78500 | J37: Retired | K37: 29 | L37: Munshiganj | M37: Dhaka | N37: Own House | O37: 3 | P37: BR-10 | Q37: BPBL Chashara Branch | R37: Narayanganj | S37: Dhaka | T37: BPBL-LN-2026-000036 | U37: Personal Loan | V37: 431000 | W37: 12.36 | X37: 24 | Y37: 46175 | Z37: 46185 | AA37: 46188 | AB37: =ROUND(PMT(W37/1200,X37,-V37),2) -> 20361.2 | AC37: 0 | AD37: 0 | AE37: 152000 | AF37: 89900 | AG37: 16 | AH37: 30600 | AI37: 730 | AJ37: =ROUND(AB37/I37,4) -> 0.2594 | AK37: =IF(AND(AI37>=750,AJ37<=0.35),"Low",IF(AND(AI37>=600,AJ37<=0.5),"Medium","High")) -> Medium | AL37: 0 | AM37: No | AN37: On Time | AO37: Approved | AP37: 0.198
A38: BPBL-CUS-000037 | B38: Aminul Sarkar | C38: Golam Rahman | D38: Male | E38: 42 | F38: Widowed | G38: Self-Employed | H38: Bachelor's | I38: 51000 | J38: Self-Employed | K38: 20 | L38: Madaripur | M38: Dhaka | N38: Rented House | O38: 2 | P38: BR-10 | Q38: BPBL Chashara Branch | R38: Narayanganj | S38: Dhaka | T38: BPBL-LN-2026-000037 | U38: Agricultural Loan | V38: 472000 | W38: 8.13 | X38: 30 | Y38: 46180 | Z38: 46185 | AA38: 46191 | AB38: =ROUND(PMT(W38/1200,X38,-V38),2) -> 17439.41 | AC38: 0 | AD38: 0 | AE38: 101400 | AF38: 35900 | AG38: 13 | AH38: 25200 | AI38: 785 | AJ38: =ROUND(AB38/I38,4) -> 0.3419 | AK38: =IF(AND(AI38>=750,AJ38<=0.35),"Low",IF(AND(AI38>=600,AJ38<=0.5),"Medium","High")) -> Low | AL38: 1 | AM38: No | AN38: On Time | AO38: Approved | AP38: 0.137
A39: BPBL-CUS-000038 | B39: Nazrul Uddin | C39: Rashedul Patwary | D39: Male | E39: 40 | F39: Married | G39: Doctor | H39: PhD | I39: 159500 | J39: Self-Employed | K39: 15 | L39: Magura | M39: Khulna | N39: Rented House | O39: 1 | P39: BR-03 | Q39: BPBL Sonadanga Branch | R39: Khulna | S39: Khulna | T39: BPBL-LN-2026-000038 | U39: Agricultural Loan | V39: 225000 | W39: 8.01 | X39: 12 | Y39: 46194 | Z39: 46198 | AA39: 46202 | AB39: =ROUND(PMT(W39/1200,X39,-V39),2) -> 19573.44 | AC39: 0 | AD39: 0 | AE39: 221900 | AF39: 97800 | AG39: 19 | AI39: 900 | AJ39: =ROUND(AB39/I39,4) -> 0.1227 | AK39: =IF(AND(AI39>=750,AJ39<=0.35),"Low",IF(AND(AI39>=600,AJ39<=0.5),"Medium","High")) -> Low | AL39: 0 | AM39: No | AN39: On Time | AO39: Approved | AP39: 0.08
A40: BPBL-CUS-000039 | B40: Ruma Sikder | C40: Quamrul Pramanik | D40: Female | E40: 30 | F40: Married | G40: Retired | H40: Master's | I40: 71500 | J40: Retired | K40: 8 | L40: Tangail | M40: Dhaka | N40: Rented House | O40: 1 | P40: BR-14 | Q40: BPBL Victoria Road Branch | R40: Tangail | S40: Dhaka | T40: BPBL-LN-2026-000039 | U40: SME Loan | V40: 1192000 | W40: 10.64 | X40: 66 | Y40: 46190 | Z40: 46198 | AA40: 46199 | AB40: =ROUND(PMT(W40/1200,X40,-V40),2) -> 23935.36 | AC40: 1534000 | AD40: 3 | AE40: 234800 | AF40: 47200 | AG40: 29 | AH40: 30800 | AI40: 751 | AJ40: =ROUND(AB40/I40,4) -> 0.3348 | AK40: =IF(AND(AI40>=750,AJ40<=0.35),"Low",IF(AND(AI40>=600,AJ40<=0.5),"Medium","High")) -> Low | AL40: 0 | AM40: No | AN40: On Time | AO40: Approved | AP40: 0.172
...

Sheet Branch_Summary
A1: Branch_ID | B1: Branch_Name | C1: Branch_City | D1: Branch_Division | E1: Total_Applications | F1: Approved_Count | G1: Rejected_Count | H1: Pending_Count | I1: Closed_Count | J1: Approval_Rate | K1: Total_Loan_Amount_Disbursed | L1: Average_Loan_Amount | M1: Average_Credit_Score | N1: Average_Interest_Rate | O1: Missed_Payment_Rate
A2: BR-01 | B2: BPBL Gulshan Branch | C2: Dhaka | D2: Dhaka | E2: =COUNTIF(Loan_Data!$P$2:$P$801,$A2) -> 56 | F2: =COUNTIFS(Loan_Data!$P$2:$P$801,$A2,Loan_Data!$AO$2:$AO$801,"Approved") -> 33 | G2: =COUNTIFS(Loan_Data!$P$2:$P$801,$A2,Loan_Data!$AO$2:$AO$801,"Rejected") -> 8 | H2: =COUNTIFS(Loan_Data!$P$2:$P$801,$A2,Loan_Data!$AO$2:$AO$801,"Pending") -> 12 | I2: =COUNTIFS(Loan_Data!$P$2:$P$801,$A2,Loan_Data!$AO$2:$AO$801,"Closed") -> 3 | J2: =IFERROR((F2+I2)/E2,0) -> 0.64285714 | K2: =SUMIFS(Loan_Data!$V$2:$V$801,Loan_Data!$P$2:$P$801,$A2,Loan_Data!$AO$2:$AO$801,"Approved")+SUMIFS(Loan_Data!$V$2:$V$801,Loan_Data!$P$2:$P$801,$A2,Loan_Data!$AO$2:$AO$801,"Closed") -> 21021000 | L2: =IFERROR(K2/(F2+I2),0) -> 583916.67 | M2: =IFERROR(AVERAGEIF(Loan_Data!$P$2:$P$801,$A2,Loan_Data!$AI$2:$AI$801),0) -> 727.39286 | N2: =IFERROR(AVERAGEIF(Loan_Data!$P$2:$P$801,$A2,Loan_Data!$W$2:$W$801),0) -> 11.508393 | O2: =IFERROR(COUNTIFS(Loan_Data!$P$2:$P$801,$A2,Loan_Data!$AN$2:$AN$801,"Missed Payment")/(F2+I2),0) -> 0.13888889
A3: BR-02 | B3: BPBL Agrabad Branch | C3: Chattogram | D3: Chattogram | E3: =COUNTIF(Loan_Data!$P$2:$P$801,$A3) -> 56 | F3: =COUNTIFS(Loan_Data!$P$2:$P$801,$A3,Loan_Data!$AO$2:$AO$801,"Approved") -> 29 | G3: =COUNTIFS(Loan_Data!$P$2:$P$801,$A3,Loan_Data!$AO$2:$AO$801,"Rejected") -> 9 | H3: =COUNTIFS(Loan_Data!$P$2:$P$801,$A3,Loan_Data!$AO$2:$AO$801,"Pending") -> 14 | I3: =COUNTIFS(Loan_Data!$P$2:$P$801,$A3,Loan_Data!$AO$2:$AO$801,"Closed") -> 4 | J3: =IFERROR((F3+I3)/E3,0) -> 0.58928571 | K3: =SUMIFS(Loan_Data!$V$2:$V$801,Loan_Data!$P$2:$P$801,$A3,Loan_Data!$AO$2:$AO$801,"Approved")+SUMIFS(Loan_Data!$V$2:$V$801,Loan_Data!$P$2:$P$801,$A3,Loan_Data!$AO$2:$AO$801,"Closed") -> 22551408 | L3: =IFERROR(K3/(F3+I3),0) -> 683376 | M3: =IFERROR(AVERAGEIF(Loan_Data!$P$2:$P$801,$A3,Loan_Data!$AI$2:$AI$801),0) -> 738.08929 | N3: =IFERROR(AVERAGEIF(Loan_Data!$P$2:$P$801,$A3,Loan_Data!$W$2:$W$801),0) -> 11.382143 | O3: =IFERROR(COUNTIFS(Loan_Data!$P$2:$P$801,$A3,Loan_Data!$AN$2:$AN$801,"Missed Payment")/(F3+I3),0) -> 0.060606061
A4: BR-03 | B4: BPBL Sonadanga Branch | C4: Khulna | D4: Khulna | E4: =COUNTIF(Loan_Data!$P$2:$P$801,$A4) -> 50 | F4: =COUNTIFS(Loan_Data!$P$2:$P$801,$A4,Loan_Data!$AO$2:$AO$801,"Approved") -> 32 | G4: =COUNTIFS(Loan_Data!$P$2:$P$801,$A4,Loan_Data!$AO$2:$AO$801,"Rejected") -> 9 | H4: =COUNTIFS(Loan_Data!$P$2:$P$801,$A4,Loan_Data!$AO$2:$AO$801,"Pending") -> 6 | I4: =COUNTIFS(Loan_Data!$P$2:$P$801,$A4,Loan_Data!$AO$2:$AO$801,"Closed") -> 3 | J4: =IFERROR((F4+I4)/E4,0) -> 0.7 | K4: =SUMIFS(Loan_Data!$V$2:$V$801,Loan_Data!$P$2:$P$801,$A4,Loan_Data!$AO$2:$AO$801,"Approved")+SUMIFS(Loan_Data!$V$2:$V$801,Loan_Data!$P$2:$P$801,$A4,Loan_Data!$AO$2:$AO$801,"Closed") -> 33174847 | L4: =IFERROR(K4/(F4+I4),0) -> 947852.77 | M4: =IFERROR(AVERAGEIF(Loan_Data!$P$2:$P$801,$A4,Loan_Data!$AI$2:$AI$801),0) -> 712.22 | N4: =IFERROR(AVERAGEIF(Loan_Data!$P$2:$P$801,$A4,Loan_Data!$W$2:$W$801),0) -> 10.7556 | O4: =IFERROR(COUNTIFS(Loan_Data!$P$2:$P$801,$A4,Loan_Data!$AN$2:$AN$801,"Missed Payment")/(F4+I4),0) -> 0.085714286
A5: BR-04 | B5: BPBL Shaheb Bazar Branch | C5: Rajshahi | D5: Rajshahi | E5: =COUNTIF(Loan_Data!$P$2:$P$801,$A5) -> 46 | F5: =COUNTIFS(Loan_Data!$P$2:$P$801,$A5,Loan_Data!$AO$2:$AO$801,"Approved") -> 27 | G5: =COUNTIFS(Loan_Data!$P$2:$P$801,$A5,Loan_Data!$AO$2:$AO$801,"Rejected") -> 5 | H5: =COUNTIFS(Loan_Data!$P$2:$P$801,$A5,Loan_Data!$AO$2:$AO$801,"Pending") -> 9 | I5: =COUNTIFS(Loan_Data!$P$2:$P$801,$A5,Loan_Data!$AO$2:$AO$801,"Closed") -> 5 | J5: =IFERROR((F5+I5)/E5,0) -> 0.69565217 | K5: =SUMIFS(Loan_Data!$V$2:$V$801,Loan_Data!$P$2:$P$801,$A5,Loan_Data!$AO$2:$AO$801,"Approved")+SUMIFS(Loan_Data!$V$2:$V$801,Loan_Data!$P$2:$P$801,$A5,Loan_Data!$AO$2:$AO$801,"Closed") -> 26347000 | L5: =IFERROR(K5/(F5+I5),0) -> 823343.75 | M5: =IFERROR(AVERAGEIF(Loan_Data!$P$2:$P$801,$A5,Loan_Data!$AI$2:$AI$801),0) -> 720.34783 | N5: =IFERROR(AVERAGEIF(Loan_Data!$P$2:$P$801,$A5,Loan_Data!$W$2:$W$801),0) -> 11.328043 | O5: =IFERROR(COUNTIFS(Loan_Data!$P$2:$P$801,$A5,Loan_Data!$AN$2:$AN$801,"Missed Payment")/(F5+I5),0) -> 0.09375
A6: BR-05 | B6: BPBL Zindabazar Branch | C6: Sylhet | D6: Sylhet | E6: =COUNTIF(Loan_Data!$P$2:$P$801,$A6) -> 51 | F6: =COUNTIFS(Loan_Data!$P$2:$P$801,$A6,Loan_Data!$AO$2:$AO$801,"Approved") -> 35 | G6: =COUNTIFS(Loan_Data!$P$2:$P$801,$A6,Loan_Data!$AO$2:$AO$801,"Rejected") -> 4 | H6: =COUNTIFS(Loan_Data!$P$2:$P$801,$A6,Loan_Data!$AO$2:$AO$801,"Pending") -> 6 | I6: =COUNTIFS(Loan_Data!$P$2:$P$801,$A6,Loan_Data!$AO$2:$AO$801,"Closed") -> 6 | J6: =IFERROR((F6+I6)/E6,0) -> 0.80392157 | K6: =SUMIFS(Loan_Data!$V$2:$V$801,Loan_Data!$P$2:$P$801,$A6,Loan_Data!$AO$2:$AO$801,"Approved")+SUMIFS(Loan_Data!$V$2:$V$801,Loan_Data!$P$2:$P$801,$A6,Loan_Data!$AO$2:$AO$801,"Closed") -> 37871092 | L6: =IFERROR(K6/(F6+I6),0) -> 923685.17 | M6: =IFERROR(AVERAGEIF(Loan_Data!$P$2:$P$801,$A6,Loan_Data!$AI$2:$AI$801),0) -> 683.58824 | N6: =IFERROR(AVERAGEIF(Loan_Data!$P$2:$P$801,$A6,Loan_Data!$W$2:$W$801),0) -> 11.452157 | O6: =IFERROR(COUNTIFS(Loan_Data!$P$2:$P$801,$A6,Loan_Data!$AN$2:$AN$801,"Missed Payment")/(F6+I6),0) -> 0.073170732
A7: BR-06 | B7: BPBL Sadar Road Branch | C7: Barishal | D7: Barishal | E7: =COUNTIF(Loan_Data!$P$2:$P$801,$A7) -> 59 | F7: =COUNTIFS(Loan_Data!$P$2:$P$801,$A7,Loan_Data!$AO$2:$AO$801,"Approved") -> 37 | G7: =COUNTIFS(Loan_Data!$P$2:$P$801,$A7,Loan_Data!$AO$2:$AO$801,"Rejected") -> 11 | H7: =COUNTIFS(Loan_Data!$P$2:$P$801,$A7,Loan_Data!$AO$2:$AO$801,"Pending") -> 4 | I7: =COUNTIFS(Loan_Data!$P$2:$P$801,$A7,Loan_Data!$AO$2:$AO$801,"Closed") -> 7 | J7: =IFERROR((F7+I7)/E7,0) -> 0.74576271 | K7: =SUMIFS(Loan_Data!$V$2:$V$801,Loan_Data!$P$2:$P$801,$A7,Loan_Data!$AO$2:$AO$801,"Approved")+SUMIFS(Loan_Data!$V$2:$V$801,Loan_Data!$P$2:$P$801,$A7,Loan_Data!$AO$2:$AO$801,"Closed") -> 35382000 | L7: =IFERROR(K7/(F7+I7),0) -> 804136.36 | M7: =IFERROR(AVERAGEIF(Loan_Data!$P$2:$P$801,$A7,Loan_Data!$AI$2:$AI$801),0) -> 719.50847 | N7: =IFERROR(AVERAGEIF(Loan_Data!$P$2:$P$801,$A7,Loan_Data!$W$2:$W$801),0) -> 11.256102 | O7: =IFERROR(COUNTIFS(Loan_Data!$P$2:$P$801,$A7,Loan_Data!$AN$2:$AN$801,"Missed Payment")/(F7+I7),0) -> 0.13636364
A8: BR-07 | B8: BPBL Jahaj Company Mor Branch | C8: Rangpur | D8: Rangpur | E8: =COUNTIF(Loan_Data!$P$2:$P$801,$A8) -> 57 | F8: =COUNTIFS(Loan_Data!$P$2:$P$801,$A8,Loan_Data!$AO$2:$AO$801,"Approved") -> 36 | G8: =COUNTIFS(Loan_Data!$P$2:$P$801,$A8,Loan_Data!$AO$2:$AO$801,"Rejected") -> 11 | H8: =COUNTIFS(Loan_Data!$P$2:$P$801,$A8,Loan_Data!$AO$2:$AO$801,"Pending") -> 8 | I8: =COUNTIFS(Loan_Data!$P$2:$P$801,$A8,Loan_Data!$AO$2:$AO$801,"Closed") -> 2 | J8: =IFERROR((F8+I8)/E8,0) -> 0.66666667 | K8: =SUMIFS(Loan_Data!$V$2:$V$801,Loan_Data!$P$2:$P$801,$A8,Loan_Data!$AO$2:$AO$801,"Approved")+SUMIFS(Loan_Data!$V$2:$V$801,Loan_Data!$P$2:$P$801,$A8,Loan_Data!$AO$2:$AO$801,"Closed") -> 23437000 | L8: =IFERROR(K8/(F8+I8),0) -> 616763.16 | M8: =IFERROR(AVERAGEIF(Loan_Data!$P$2:$P$801,$A8,Loan_Data!$AI$2:$AI$801),0) -> 728.64912 | N8: =IFERROR(AVERAGEIF(Loan_Data!$P$2:$P$801,$A8,Loan_Data!$W$2:$W$801),0) -> 11.434737 | O8: =IFERROR(COUNTIFS(Loan_Data!$P$2:$P$801,$A8,Loan_Data!$AN$2:$AN$801,"Missed Payment")/(F8+I8),0) -> 0.078947368
A9: BR-08 | B9: BPBL Notun Bazar Branch | C9: Mymensingh | D9: Mymensingh | E9: =COUNTIF(Loan_Data!$P$2:$P$801,$A9) -> 48 | F9: =COUNTIFS(Loan_Data!$P$2:$P$801,$A9,Loan_Data!$AO$2:$AO$801,"Approved") -> 26 | G9: =COUNTIFS(Loan_Data!$P$2:$P$801,$A9,Loan_Data!$AO$2:$AO$801,"Rejected") -> 8 | H9: =COUNTIFS(Loan_Data!$P$2:$P$801,$A9,Loan_Data!$AO$2:$AO$801,"Pending") -> 10 | I9: =COUNTIFS(Loan_Data!$P$2:$P$801,$A9,Loan_Data!$AO$2:$AO$801,"Closed") -> 4 | J9: =IFERROR((F9+I9)/E9,0) -> 0.625 | K9: =SUMIFS(Loan_Data!$V$2:$V$801,Loan_Data!$P$2:$P$801,$A9,Loan_Data!$AO$2:$AO$801,"Approved")+SUMIFS(Loan_Data!$V$2:$V$801,Loan_Data!$P$2:$P$801,$A9,Loan_Data!$AO$2:$AO$801,"Closed") -> 16662000 | L9: =IFERROR(K9/(F9+I9),0) -> 555400 | M9: =IFERROR(AVERAGEIF(Loan_Data!$P$2:$P$801,$A9,Loan_Data!$AI$2:$AI$801),0) -> 689.45833 | N9: =IFERROR(AVERAGEIF(Loan_Data!$P$2:$P$801,$A9,Loan_Data!$W$2:$W$801),0) -> 11.199583 | O9: =IFERROR(COUNTIFS(Loan_Data!$P$2:$P$801,$A9,Loan_Data!$AN$2:$AN$801,"Missed Payment")/(F9+I9),0) -> 0.16666667
A10: BR-09 | B10: BPBL Chandona Chowrasta Branch | C10: Gazipur | D10: Dhaka | E10: =COUNTIF(Loan_Data!$P$2:$P$801,$A10) -> 44 | F10: =COUNTIFS(Loan_Data!$P$2:$P$801,$A10,Loan_Data!$AO$2:$AO$801,"Approved") -> 26 | G10: =COUNTIFS(Loan_Data!$P$2:$P$801,$A10,Loan_Data!$AO$2:$AO$801,"Rejected") -> 9 | H10: =COUNTIFS(Loan_Data!$P$2:$P$801,$A10,Loan_Data!$AO$2:$AO$801,"Pending") -> 5 | I10: =COUNTIFS(Loan_Data!$P$2:$P$801,$A10,Loan_Data!$AO$2:$AO$801,"Closed") -> 4 | J10: =IFERROR((F10+I10)/E10,0) -> 0.68181818 | K10: =SUMIFS(Loan_Data!$V$2:$V$801,Loan_Data!$P$2:$P$801,$A10,Loan_Data!$AO$2:$AO$801,"Approved")+SUMIFS(Loan_Data!$V$2:$V$801,Loan_Data!$P$2:$P$801,$A10,Loan_Data!$AO$2:$AO$801,"Closed") -> 27697563 | L10: =IFERROR(K10/(F10+I10),0) -> 923252.1 | M10: =IFERROR(AVERAGEIF(Loan_Data!$P$2:$P$801,$A10,Loan_Data!$AI$2:$AI$801),0) -> 717.63636 | N10: =IFERROR(AVERAGEIF(Loan_Data!$P$2:$P$801,$A10,Loan_Data!$W$2:$W$801),0) -> 10.917727 | O10: =IFERROR(COUNTIFS(Loan_Data!$P$2:$P$801,$A10,Loan_Data!$AN$2:$AN$801,"Missed Payment")/(F10+I10),0) -> 0.1
A11: BR-10 | B11: BPBL Chashara Branch | C11: Narayanganj | D11: Dhaka | E11: =COUNTIF(Loan_Data!$P$2:$P$801,$A11) -> 57 | F11: =COUNTIFS(Loan_Data!$P$2:$P$801,$A11,Loan_Data!$AO$2:$AO$801,"Approved") -> 40 | G11: =COUNTIFS(Loan_Data!$P$2:$P$801,$A11,Loan_Data!$AO$2:$AO$801,"Rejected") -> 7 | H11: =COUNTIFS(Loan_Data!$P$2:$P$801,$A11,Loan_Data!$AO$2:$AO$801,"Pending") -> 10 | I11: =COUNTIFS(Loan_Data!$P$2:$P$801,$A11,Loan_Data!$AO$2:$AO$801,"Closed") -> 0 | J11: =IFERROR((F11+I11)/E11,0) -> 0.70175439 | K11: =SUMIFS(Loan_Data!$V$2:$V$801,Loan_Data!$P$2:$P$801,$A11,Loan_Data!$AO$2:$AO$801,"Approved")+SUMIFS(Loan_Data!$V$2:$V$801,Loan_Data!$P$2:$P$801,$A11,Loan_Data!$AO$2:$AO$801,"Closed") -> 32822000 | L11: =IFERROR(K11/(F11+I11),0) -> 820550 | M11: =IFERROR(AVERAGEIF(Loan_Data!$P$2:$P$801,$A11,Loan_Data!$AI$2:$AI$801),0) -> 715.15789 | N11: =IFERROR(AVERAGEIF(Loan_Data!$P$2:$P$801,$A11,Loan_Data!$W$2:$W$801),0) -> 11.304912 | O11: =IFERROR(COUNTIFS(Loan_Data!$P$2:$P$801,$A11,Loan_Data!$AN$2:$AN$801,"Missed Payment")/(F11+I11),0) -> 0.05
A12: BR-11 | B12: BPBL Kandirpar Branch | C12: Cumilla | D12: Chattogram | E12: =COUNTIF(Loan_Data!$P$2:$P$801,$A12) -> 43 | F12: =COUNTIFS(Loan_Data!$P$2:$P$801,$A12,Loan_Data!$AO$2:$AO$801,"Approved") -> 26 | G12: =COUNTIFS(Loan_Data!$P$2:$P$801,$A12,Loan_Data!$AO$2:$AO$801,"Rejected") -> 7 | H12: =COUNTIFS(Loan_Data!$P$2:$P$801,$A12,Loan_Data!$AO$2:$AO$801,"Pending") -> 8 | I12: =COUNTIFS(Loan_Data!$P$2:$P$801,$A12,Loan_Data!$AO$2:$AO$801,"Closed") -> 2 | J12: =IFERROR((F12+I12)/E12,0) -> 0.65116279 | K12: =SUMIFS(Loan_Data!$V$2:$V$801,Loan_Data!$P$2:$P$801,$A12,Loan_Data!$AO$2:$AO$801,"Approved")+SUMIFS(Loan_Data!$V$2:$V$801,Loan_Data!$P$2:$P$801,$A12,Loan_Data!$AO$2:$AO$801,"Closed") -> 20701000 | L12: =IFERROR(K12/(F12+I12),0) -> 739321.43 | M12: =IFERROR(AVERAGEIF(Loan_Data!$P$2:$P$801,$A12,Loan_Data!$AI$2:$AI$801),0) -> 725.60465 | N12: =IFERROR(AVERAGEIF(Loan_Data!$P$2:$P$801,$A12,Loan_Data!$W$2:$W$801),0) -> 11.048372 | O12: =IFERROR(COUNTIFS(Loan_Data!$P$2:$P$801,$A12,Loan_Data!$AN$2:$AN$801,"Missed Payment")/(F12+I12),0) -> 0.14285714
A13: BR-12 | B13: BPBL Satmatha Branch | C13: Bogura | D13: Rajshahi | E13: =COUNTIF(Loan_Data!$P$2:$P$801,$A13) -> 67 | F13: =COUNTIFS(Loan_Data!$P$2:$P$801,$A13,Loan_Data!$AO$2:$AO$801,"Approved") -> 38 | G13: =COUNTIFS(Loan_Data!$P$2:$P$801,$A13,Loan_Data!$AO$2:$AO$801,"Rejected") -> 14 | H13: =COUNTIFS(Loan_Data!$P$2:$P$801,$A13,Loan_Data!$AO$2:$AO$801,"Pending") -> 9 | I13: =COUNTIFS(Loan_Data!$P$2:$P$801,$A13,Loan_Data!$AO$2:$AO$801,"Closed") -> 6 | J13: =IFERROR((F13+I13)/E13,0) -> 0.65671642 | K13: =SUMIFS(Loan_Data!$V$2:$V$801,Loan_Data!$P$2:$P$801,$A13,Loan_Data!$AO$2:$AO$801,"Approved")+SUMIFS(Loan_Data!$V$2:$V$801,Loan_Data!$P$2:$P$801,$A13,Loan_Data!$AO$2:$AO$801,"Closed") -> 38943552 | L13: =IFERROR(K13/(F13+I13),0) -> 885080.73 | M13: =IFERROR(AVERAGEIF(Loan_Data!$P$2:$P$801,$A13,Loan_Data!$AI$2:$AI$801),0) -> 722.34328 | N13: =IFERROR(AVERAGEIF(Loan_Data!$P$2:$P$801,$A13,Loan_Data!$W$2:$W$801),0) -> 11.041642 | O13: =IFERROR(COUNTIFS(Loan_Data!$P$2:$P$801,$A13,Loan_Data!$AN$2:$AN$801,"Missed Payment")/(F13+I13),0) -> 0.045454545
... A16: BR-15 | B16: BPBL Maijdee Court Branch | C16: Noakhali | D16: Chattogram | E16: =COUNTIF(Loan_Data!$P$2:$P$801,$A16) -> 52 | F16: =COUNTIFS(Loan_Data!$P$2:$P$801,$A16,Loan_Data!$AO$2:$AO$801,"Approved") -> 31 | G16: =COUNTIFS(Loan_Data!$P$2:$P$801,$A16,Loan_Data!$AO$2:$AO$801,"Rejected") -> 8 | H16: =COUNTIFS(Loan_Data!$P$2:$P$801,$A16,Loan_Data!$AO$2:$AO$801,"Pending") -> 10 | I16: =COUNTIFS(Loan_Data!$P$2:$P$801,$A16,Loan_Data!$AO$2:$AO$801,"Closed") -> 3 | J16: =IFERROR((F16+I16)/E16,0) -> 0.65384615 | K16: =SUMIFS(Loan_Data!$V$2:$V$801,Loan_Data!$P$2:$P$801,$A16,Loan_Data!$AO$2:$AO$801,"Approved")+SUMIFS(Loan_Data!$V$2:$V$801,Loan_Data!$P$2:$P$801,$A16,Loan_Data!$AO$2:$AO$801,"Closed") -> 27393000 | L16: =IFERROR(K16/(F16+I16),0) -> 805676.47 | M16: =IFERROR(AVERAGEIF(Loan_Data!$P$2:$P$801,$A16,Loan_Data!$AI$2:$AI$801),0) -> 703.30769 | N16: =IFERROR(AVERAGEIF(Loan_Data!$P$2:$P$801,$A16,Loan_Data!$W$2:$W$801),0) -> 11.354231 | O16: =IFERROR(COUNTIFS(Loan_Data!$P$2:$P$801,$A16,Loan_Data!$AN$2:$AN$801,"Missed Payment")/(F16+I16),0) -> 0.14705882
A17: TOTAL / OVERALL | E17: =SUM(E2:E16) -> 800 | F17: =SUM(F2:F16) -> 480 | G17: =SUM(G2:G16) -> 134 | H17: =SUM(H2:H16) -> 126 | I17: =SUM(I2:I16) -> 60 | J17: =IFERROR((F17+I17)/E17,0) -> 0.675 | K17: =SUM(K2:K16) -> 416564462 | L17: =IFERROR(K17/(F17+I17),0) -> 771415.67 | M17: =AVERAGE(M2:M16) -> 715.80272 | N17: =AVERAGE(N2:N16) -> 11.280255 | O17: =IFERROR(SUMPRODUCT(O2:O16,(F2:F16+I2:I16))/(F17+I17),0) -> 0.094444444

Sheet Loan_Type_Summary
A1: Loan_Type | B1: Total_Applications | C1: Approved_Count | D1: Rejected_Count | E1: Pending_Count | F1: Closed_Count | G1: Approval_Rate | H1: Total_Loan_Amount_Disbursed | I1: Average_Loan_Amount | J1: Average_Interest_Rate | K1: Average_Loan_Term_Months | L1: Average_EMI_Amount | M1: Average_DTI | N1: Average_Credit_Score | O1: Missed_Payment_Rate
A2: Agricultural Loan | B2: =COUNTIF(Loan_Data!$U$2:$U$801,$A2) -> 161 | C2: =COUNTIFS(Loan_Data!$U$2:$U$801,$A2,Loan_Data!$AO$2:$AO$801,"Approved") -> 93 | D2: =COUNTIFS(Loan_Data!$U$2:$U$801,$A2,Loan_Data!$AO$2:$AO$801,"Rejected") -> 29 | E2: =COUNTIFS(Loan_Data!$U$2:$U$801,$A2,Loan_Data!$AO$2:$AO$801,"Pending") -> 25 | F2: =COUNTIFS(Loan_Data!$U$2:$U$801,$A2,Loan_Data!$AO$2:$AO$801,"Closed") -> 14 | G2: =IFERROR((C2+F2)/B2,0) -> 0.66459627 | H2: =SUMIFS(Loan_Data!$V$2:$V$801,Loan_Data!$U$2:$U$801,$A2,Loan_Data!$AO$2:$AO$801,"Approved")+SUMIFS(Loan_Data!$V$2:$V$801,Loan_Data!$U$2:$U$801,$A2,Loan_Data!$AO$2:$AO$801,"Closed") -> 38406939 | I2: =IFERROR(H2/(C2+F2),0) -> 358943.36 | J2: =IFERROR(AVERAGEIF(Loan_Data!$U$2:$U$801,$A2,Loan_Data!$W$2:$W$801),0) -> 8.9537888 | K2: =IFERROR(AVERAGEIF(Loan_Data!$U$2:$U$801,$A2,Loan_Data!$X$2:$X$801),0) -> 20.161491 | L2: =IFERROR(AVERAGEIF(Loan_Data!$U$2:$U$801,$A2,Loan_Data!$AB$2:$AB$801),0) -> 18626.617 | M2: =IFERROR(AVERAGEIF(Loan_Data!$U$2:$U$801,$A2,Loan_Data!$AJ$2:$AJ$801),0) -> 0.52606584 | N2: =IFERROR(AVERAGEIF(Loan_Data!$U$2:$U$801,$A2,Loan_Data!$AI$2:$AI$801),0) -> 718.20497 | O2: =IFERROR(COUNTIFS(Loan_Data!$U$2:$U$801,$A2,Loan_Data!$AN$2:$AN$801,"Missed Payment")/(C2+F2),0) -> 0.08411215
A3: Business Loan | B3: =COUNTIF(Loan_Data!$U$2:$U$801,$A3) -> 115 | C3: =COUNTIFS(Loan_Data!$U$2:$U$801,$A3,Loan_Data!$AO$2:$AO$801,"Approved") -> 58 | D3: =COUNTIFS(Loan_Data!$U$2:$U$801,$A3,Loan_Data!$AO$2:$AO$801,"Rejected") -> 22 | E3: =COUNTIFS(Loan_Data!$U$2:$U$801,$A3,Loan_Data!$AO$2:$AO$801,"Pending") -> 20 | F3: =COUNTIFS(Loan_Data!$U$2:$U$801,$A3,Loan_Data!$AO$2:$AO$801,"Closed") -> 15 | G3: =IFERROR((C3+F3)/B3,0) -> 0.63478261 | H3: =SUMIFS(Loan_Data!$V$2:$V$801,Loan_Data!$U$2:$U$801,$A3,Loan_Data!$AO$2:$AO$801,"Approved")+SUMIFS(Loan_Data!$V$2:$V$801,Loan_Data!$U$2:$U$801,$A3,Loan_Data!$AO$2:$AO$801,"Closed") -> 59206000 | I3: =IFERROR(H3/(C3+F3),0) -> 811041.1 | J3: =IFERROR(AVERAGEIF(Loan_Data!$U$2:$U$801,$A3,Loan_Data!$W$2:$W$801),0) -> 13.958435 | K3: =IFERROR(AVERAGEIF(Loan_Data!$U$2:$U$801,$A3,Loan_Data!$X$2:$X$801),0) -> 50.13913 | L3: =IFERROR(AVERAGEIF(Loan_Data!$U$2:$U$801,$A3,Loan_Data!$AB$2:$AB$801),0) -> 22618.573 | M3: =IFERROR(AVERAGEIF(Loan_Data!$U$2:$U$801,$A3,Loan_Data!$AJ$2:$AJ$801),0) -> 0.38472522 | N3: =IFERROR(AVERAGEIF(Loan_Data!$U$2:$U$801,$A3,Loan_Data!$AI$2:$AI$801),0) -> 704.06957 | O3: =IFERROR(COUNTIFS(Loan_Data!$U$2:$U$801,$A3,Loan_Data!$AN$2:$AN$801,"Missed Payment")/(C3+F3),0) -> 0.054794521
A4: Car Loan | B4: =COUNTIF(Loan_Data!$U$2:$U$801,$A4) -> 123 | C4: =COUNTIFS(Loan_Data!$U$2:$U$801,$A4,Loan_Data!$AO$2:$AO$801,"Approved") -> 82 | D4: =COUNTIFS(Loan_Data!$U$2:$U$801,$A4,Loan_Data!$AO$2:$AO$801,"Rejected") -> 14 | E4: =COUNTIFS(Loan_Data!$U$2:$U$801,$A4,Loan_Data!$AO$2:$AO$801,"Pending") -> 21 | F4: =COUNTIFS(Loan_Data!$U$2:$U$801,$A4,Loan_Data!$AO$2:$AO$801,"Closed") -> 6 | G4: =IFERROR((C4+F4)/B4,0) -> 0.71544715 | H4: =SUMIFS(Loan_Data!$V$2:$V$801,Loan_Data!$U$2:$U$801,$A4,Loan_Data!$AO$2:$AO$801,"Approved")+SUMIFS(Loan_Data!$V$2:$V$801,Loan_Data!$U$2:$U$801,$A4,Loan_Data!$AO$2:$AO$801,"Closed") -> 67399563 | I4: =IFERROR(H4/(C4+F4),0) -> 765904.12 | J4: =IFERROR(AVERAGEIF(Loan_Data!$U$2:$U$801,$A4,Loan_Data!$W$2:$W$801),0) -> 11.44561 | K4: =IFERROR(AVERAGEIF(Loan_Data!$U$2:$U$801,$A4,Loan_Data!$X$2:$X$801),0) -> 43.463415 | L4: =IFERROR(AVERAGEIF(Loan_Data!$U$2:$U$801,$A4,Loan_Data!$AB$2:$AB$801),0) -> 22908.72 | M4: =IFERROR(AVERAGEIF(Loan_Data!$U$2:$U$801,$A4,Loan_Data!$AJ$2:$AJ$801),0) -> 0.44876992 | N4: =IFERROR(AVERAGEIF(Loan_Data!$U$2:$U$801,$A4,Loan_Data!$AI$2:$AI$801),0) -> 715.76423 | O4: =IFERROR(COUNTIFS(Loan_Data!$U$2:$U$801,$A4,Loan_Data!$AN$2:$AN$801,"Missed Payment")/(C4+F4),0) -> 0.17045455
A5: Education Loan | B5: =COUNTIF(Loan_Data!$U$2:$U$801,$A5) -> 96 | C5: =COUNTIFS(Loan_Data!$U$2:$U$801,$A5,Loan_Data!$AO$2:$AO$801,"Approved") -> 59 | D5: =COUNTIFS(Loan_Data!$U$2:$U$801,$A5,Loan_Data!$AO$2:$AO$801,"Rejected") -> 16 | E5: =COUNTIFS(Loan_Data!$U$2:$U$801,$A5,Loan_Data!$AO$2:$AO$801,"Pending") -> 17 | F5: =COUNTIFS(Loan_Data!$U$2:$U$801,$A5,Loan_Data!$AO$2:$AO$801,"Closed") -> 4 | G5: =IFERROR((C5+F5)/B5,0) -> 0.65625 | H5: =SUMIFS(Loan_Data!$V$2:$V$801,Loan_Data!$U$2:$U$801,$A5,Loan_Data!$AO$2:$AO$801,"Approved")+SUMIFS(Loan_Data!$V$2:$V$801,Loan_Data!$U$2:$U$801,$A5,Loan_Data!$AO$2:$AO$801,"Closed") -> 48619635 | I5: =IFERROR(H5/(C5+F5),0) -> 771740.24 | J5: =IFERROR(AVERAGEIF(Loan_Data!$U$2:$U$801,$A5,Loan_Data!$W$2:$W$801),0) -> 9.1025 | K5: =IFERROR(AVERAGEIF(Loan_Data!$U$2:$U$801,$A5,Loan_Data!$X$2:$X$801),0) -> 47.3125 | L5: =IFERROR(AVERAGEIF(Loan_Data!$U$2:$U$801,$A5,Loan_Data!$AB$2:$AB$801),0) -> 21990.886 | M5: =IFERROR(AVERAGEIF(Loan_Data!$U$2:$U$801,$A5,Loan_Data!$AJ$2:$AJ$801),0) -> 0.50934167 | N5: =IFERROR(AVERAGEIF(Loan_Data!$U$2:$U$801,$A5,Loan_Data!$AI$2:$AI$801),0) -> 711.22917 | O5: =IFERROR(COUNTIFS(Loan_Data!$U$2:$U$801,$A5,Loan_Data!$AN$2:$AN$801,"Missed Payment")/(C5+F5),0) -> 0.031746032
A6: Home Loan | B6: =COUNTIF(Loan_Data!$U$2:$U$801,$A6) -> 88 | C6: =COUNTIFS(Loan_Data!$U$2:$U$801,$A6,Loan_Data!$AO$2:$AO$801,"Approved") -> 50 | D6: =COUNTIFS(Loan_Data!$U$2:$U$801,$A6,Loan_Data!$AO$2:$AO$801,"Rejected") -> 16 | E6: =COUNTIFS(Loan_Data!$U$2:$U$801,$A6,Loan_Data!$AO$2:$AO$801,"Pending") -> 18 | F6: =COUNTIFS(Loan_Data!$U$2:$U$801,$A6,Loan_Data!$AO$2:$AO$801,"Closed") -> 4 | G6: =IFERROR((C6+F6)/B6,0) -> 0.61363636 | H6: =SUMIFS(Loan_Data!$V$2:$V$801,Loan_Data!$U$2:$U$801,$A6,Loan_Data!$AO$2:$AO$801,"Approved")+SUMIFS(Loan_Data!$V$2:$V$801,Loan_Data!$U$2:$U$801,$A6,Loan_Data!$AO$2:$AO$801,"Closed") -> 103104000 | I6: =IFERROR(H6/(C6+F6),0) -> 1909333.3 | J6: =IFERROR(AVERAGEIF(Loan_Data!$U$2:$U$801,$A6,Loan_Data!$W$2:$W$801),0) -> 10.064432 | K6: =IFERROR(AVERAGEIF(Loan_Data!$U$2:$U$801,$A6,Loan_Data!$X$2:$X$801),0) -> 182.79545 | L6: =IFERROR(AVERAGEIF(Loan_Data!$U$2:$U$801,$A6,Loan_Data!$AB$2:$AB$801),0) -> 21034.877 | M6: =IFERROR(AVERAGEIF(Loan_Data!$U$2:$U$801,$A6,Loan_Data!$AJ$2:$AJ$801),0) -> 0.3961125 | N6: =IFERROR(AVERAGEIF(Loan_Data!$U$2:$U$801,$A6,Loan_Data!$AI$2:$AI$801),0) -> 726.36364 | O6: =IFERROR(COUNTIFS(Loan_Data!$U$2:$U$801,$A6,Loan_Data!$AN$2:$AN$801,"Missed Payment")/(C6+F6),0) -> 0.14814815
A7: Personal Loan | B7: =COUNTIF(Loan_Data!$U$2:$U$801,$A7) -> 93 | C7: =COUNTIFS(Loan_Data!$U$2:$U$801,$A7,Loan_Data!$AO$2:$AO$801,"Approved") -> 61 | D7: =COUNTIFS(Loan_Data!$U$2:$U$801,$A7,Loan_Data!$AO$2:$AO$801,"Rejected") -> 14 | E7: =COUNTIFS(Loan_Data!$U$2:$U$801,$A7,Loan_Data!$AO$2:$AO$801,"Pending") -> 9 | F7: =COUNTIFS(Loan_Data!$U$2:$U$801,$A7,Loan_Data!$AO$2:$AO$801,"Closed") -> 9 | G7: =IFERROR((C7+F7)/B7,0) -> 0.75268817 | H7: =SUMIFS(Loan_Data!$V$2:$V$801,Loan_Data!$U$2:$U$801,$A7,Loan_Data!$AO$2:$AO$801,"Approved")+SUMIFS(Loan_Data!$V$2:$V$801,Loan_Data!$U$2:$U$801,$A7,Loan_Data!$AO$2:$AO$801,"Closed") -> 38829000 | I7: =IFERROR(H7/(C7+F7),0) -> 554700 | J7: =IFERROR(AVERAGEIF(Loan_Data!$U$2:$U$801,$A7,Loan_Data!$W$2:$W$801),0) -> 13.686344 | K7: =IFERROR(AVERAGEIF(Loan_Data!$U$2:$U$801,$A7,Loan_Data!$X$2:$X$801),0) -> 35.419355 | L7: =IFERROR(AVERAGEIF(Loan_Data!$U$2:$U$801,$A7,Loan_Data!$AB$2:$AB$801),0) -> 20662.786 | M7: =IFERROR(AVERAGEIF(Loan_Data!$U$2:$U$801,$A7,Loan_Data!$AJ$2:$AJ$801),0) -> 0.3351957 | N7: =IFERROR(AVERAGEIF(Loan_Data!$U$2:$U$801,$A7,Loan_Data!$AI$2:$AI$801),0) -> 718.29032 | O7: =IFERROR(COUNTIFS(Loan_Data!$U$2:$U$801,$A7,Loan_Data!$AN$2:$AN$801,"Missed Payment")/(C7+F7),0) -> 0.085714286
A8: SME Loan | B8: =COUNTIF(Loan_Data!$U$2:$U$801,$A8) -> 124 | C8: =COUNTIFS(Loan_Data!$U$2:$U$801,$A8,Loan_Data!$AO$2:$AO$801,"Approved") -> 77 | D8: =COUNTIFS(Loan_Data!$U$2:$U$801,$A8,Loan_Data!$AO$2:$AO$801,"Rejected") -> 23 | E8: =COUNTIFS(Loan_Data!$U$2:$U$801,$A8,Loan_Data!$AO$2:$AO$801,"Pending") -> 16 | F8: =COUNTIFS(Loan_Data!$U$2:$U$801,$A8,Loan_Data!$AO$2:$AO$801,"Closed") -> 8 | G8: =IFERROR((C8+F8)/B8,0) -> 0.68548387 | H8: =SUMIFS(Loan_Data!$V$2:$V$801,Loan_Data!$U$2:$U$801,$A8,Loan_Data!$AO$2:$AO$801,"Approved")+SUMIFS(Loan_Data!$V$2:$V$801,Loan_Data!$U$2:$U$801,$A8,Loan_Data!$AO$2:$AO$801,"Closed") -> 60999325 | I8: =IFERROR(H8/(C8+F8),0) -> 717639.12 | J8: =IFERROR(AVERAGEIF(Loan_Data!$U$2:$U$801,$A8,Loan_Data!$W$2:$W$801),0) -> 12.459194 | K8: =IFERROR(AVERAGEIF(Loan_Data!$U$2:$U$801,$A8,Loan_Data!$X$2:$X$801),0) -> 44.709677 | L8: =IFERROR(AVERAGEIF(Loan_Data!$U$2:$U$801,$A8,Loan_Data!$AB$2:$AB$801),0) -> 21058.642 | M8: =IFERROR(AVERAGEIF(Loan_Data!$U$2:$U$801,$A8,Loan_Data!$AJ$2:$AJ$801),0) -> 0.4049871 | N8: =IFERROR(AVERAGEIF(Loan_Data!$U$2:$U$801,$A8,Loan_Data!$AI$2:$AI$801),0) -> 720.57258 | O8: =IFERROR(COUNTIFS(Loan_Data!$U$2:$U$801,$A8,Loan_Data!$AN$2:$AN$801,"Missed Payment")/(C8+F8),0) -> 0.082352941
A9: TOTAL / OVERALL | B9: =SUM(B2:B8) -> 800 | C9: =SUM(C2:C8) -> 480 | D9: =SUM(D2:D8) -> 134 | E9: =SUM(E2:E8) -> 126 | F9: =SUM(F2:F8) -> 60 | G9: =IFERROR((C9+F9)/B9,0) -> 0.675 | H9: =SUM(H2:H8) -> 416564462 | I9: =IFERROR(H9/(C9+F9),0) -> 771415.67 | J9: =AVERAGE(J2:J8) -> 11.381472 | K9: =AVERAGE(K2:K8) -> 60.571575 | L9: =AVERAGE(L2:L8) -> 21271.586 | M9: =AVERAGE(M2:M8) -> 0.42931399 | N9: =AVERAGE(N2:N8) -> 716.35635 | O9: =IFERROR(SUMPRODUCT(O2:O8,(C2:C8+F2:F8))/(C9+F9),0) -> 0.094444444

Sheet Risk_Analysis
A1: Risk_Level | B1: Total_Count | C1: Pct_of_Total | D1: Approved_Count | E1: Rejected_Count | F1: Pending_Count | G1: Closed_Count | H1: Approval_Rate | I1: Total_Loan_Amount_Disbursed | J1: Average_Loan_Amount | K1: Average_Credit_Score | L1: Average_Interest_Rate | M1: Average_DTI | N1: Average_Default_Probability | O1: Missed_Payment_Rate | P1: Previous_Default_Rate
A2: Low | B2: =COUNTIF(Loan_Data!$AK$2:$AK$801,$A2) -> 164 | C2: =IFERROR(B2/COUNTA(Loan_Data!$AK$2:$AK$801),0) -> 0.205 | D2: =COUNTIFS(Loan_Data!$AK$2:$AK$801,$A2,Loan_Data!$AO$2:$AO$801,"Approved") -> 110 | E2: =COUNTIFS(Loan_Data!$AK$2:$AK$801,$A2,Loan_Data!$AO$2:$AO$801,"Rejected") -> 9 | F2: =COUNTIFS(Loan_Data!$AK$2:$AK$801,$A2,Loan_Data!$AO$2:$AO$801,"Pending") -> 26 | G2: =COUNTIFS(Loan_Data!$AK$2:$AK$801,$A2,Loan_Data!$AO$2:$AO$801,"Closed") -> 19 | H2: =IFERROR((D2+G2)/B2,0) -> 0.78658537 | I2: =SUMIFS(Loan_Data!$V$2:$V$801,Loan_Data!$AK$2:$AK$801,$A2,Loan_Data!$AO$2:$AO$801,"Approved")+SUMIFS(Loan_Data!$V$2:$V$801,Loan_Data!$AK$2:$AK$801,$A2,Loan_Data!$AO$2:$AO$801,"Closed") -> 94401000 | J2: =IFERROR(I2/(D2+G2),0) -> 731790.7 | K2: =IFERROR(AVERAGEIF(Loan_Data!$AK$2:$AK$801,$A2,Loan_Data!$AI$2:$AI$801),0) -> 817.5122 | L2: =IFERROR(AVERAGEIF(Loan_Data!$AK$2:$AK$801,$A2,Loan_Data!$W$2:$W$801),0) -> 11.041524 | M2: =IFERROR(AVERAGEIF(Loan_Data!$AK$2:$AK$801,$A2,Loan_Data!$AJ$2:$AJ$801),0) -> 0.25651037 | N2: =IFERROR(AVERAGEIF(Loan_Data!$AK$2:$AK$801,$A2,Loan_Data!$AP$2:$AP$801),0) -> 0.13630488 | O2: =IFERROR(COUNTIFS(Loan_Data!$AK$2:$AK$801,$A2,Loan_Data!$AN$2:$AN$801,"Missed Payment")/(D2+G2),0) -> 0.023255814 | P2: =IFERROR(COUNTIFS(Loan_Data!$AK$2:$AK$801,$A2,Loan_Data!$AM$2:$AM$801,"Yes")/B2,0) -> 0.10365854
A3: Medium | B3: =COUNTIF(Loan_Data!$AK$2:$AK$801,$A3) -> 456 | C3: =IFERROR(B3/COUNTA(Loan_Data!$AK$2:$AK$801),0) -> 0.57 | D3: =COUNTIFS(Loan_Data!$AK$2:$AK$801,$A3,Loan_Data!$AO$2:$AO$801,"Approved") -> 278 | E3: =COUNTIFS(Loan_Data!$AK$2:$AK$801,$A3,Loan_Data!$AO$2:$AO$801,"Rejected") -> 77 | F3: =COUNTIFS(Loan_Data!$AK$2:$AK$801,$A3,Loan_Data!$AO$2:$AO$801,"Pending") -> 73 | G3: =COUNTIFS(Loan_Data!$AK$2:$AK$801,$A3,Loan_Data!$AO$2:$AO$801,"Closed") -> 28 | H3: =IFERROR((D3+G3)/B3,0) -> 0.67105263 | I3: =SUMIFS(Loan_Data!$V$2:$V$801,Loan_Data!$AK$2:$AK$801,$A3,Loan_Data!$AO$2:$AO$801,"Approved")+SUMIFS(Loan_Data!$V$2:$V$801,Loan_Data!$AK$2:$AK$801,$A3,Loan_Data!$AO$2:$AO$801,"Closed") -> 236567000 | J3: =IFERROR(I3/(D3+G3),0) -> 773094.77 | K3: =IFERROR(AVERAGEIF(Loan_Data!$AK$2:$AK$801,$A3,Loan_Data!$AI$2:$AI$801),0) -> 706.70833 | L3: =IFERROR(AVERAGEIF(Loan_Data!$AK$2:$AK$801,$A3,Loan_Data!$W$2:$W$801),0) -> 11.324342 | M3: =IFERROR(AVERAGEIF(Loan_Data!$AK$2:$AK$801,$A3,Loan_Data!$AJ$2:$AJ$801),0) -> 0.3425 | N3: =IFERROR(AVERAGEIF(Loan_Data!$AK$2:$AK$801,$A3,Loan_Data!$AP$2:$AP$801),0) -> 0.25341886 | O3: =IFERROR(COUNTIFS(Loan_Data!$AK$2:$AK$801,$A3,Loan_Data!$AN$2:$AN$801,"Missed Payment")/(D3+G3),0) -> 0.075163399 | P3: =IFERROR(COUNTIFS(Loan_Data!$AK$2:$AK$801,$A3,Loan_Data!$AM$2:$AM$801,"Yes")/B3,0) -> 0.15570175
A4: High | B4: =COUNTIF(Loan_Data!$AK$2:$AK$801,$A4) -> 180 | C4: =IFERROR(B4/COUNTA(Loan_Data!$AK$2:$AK$801),0) -> 0.225 | D4: =COUNTIFS(Loan_Data!$AK$2:$AK$801,$A4,Loan_Data!$AO$2:$AO$801,"Approved") -> 92 | E4: =COUNTIFS(Loan_Data!$AK$2:$AK$801,$A4,Loan_Data!$AO$2:$AO$801,"Rejected") -> 48 | F4: =COUNTIFS(Loan_Data!$AK$2:$AK$801,$A4,Loan_Data!$AO$2:$AO$801,"Pending") -> 27 | G4: =COUNTIFS(Loan_Data!$AK$2:$AK$801,$A4,Loan_Data!$AO$2:$AO$801,"Closed") -> 13 | H4: =IFERROR((D4+G4)/B4,0) -> 0.58333333 | I4: =SUMIFS(Loan_Data!$V$2:$V$801,Loan_Data!$AK$2:$AK$801,$A4,Loan_Data!$AO$2:$AO$801,"Approved")+SUMIFS(Loan_Data!$V$2:$V$801,Loan_Data!$AK$2:$AK$801,$A4,Loan_Data!$AO$2:$AO$801,"Closed") -> 85596462 | J4: =IFERROR(I4/(D4+G4),0) -> 815204.4 | K4: =IFERROR(AVERAGEIF(Loan_Data!$AK$2:$AK$801,$A4,Loan_Data!$AI$2:$AI$801),0) -> 648.09444 | L4: =IFERROR(AVERAGEIF(Loan_Data!$AK$2:$AK$801,$A4,Loan_Data!$W$2:$W$801),0) -> 11.428667 | M4: =IFERROR(AVERAGEIF(Loan_Data!$AK$2:$AK$801,$A4,Loan_Data!$AJ$2:$AJ$801),0) -> 0.83909611 | N4: =IFERROR(AVERAGEIF(Loan_Data!$AK$2:$AK$801,$A4,Loan_Data!$AP$2:$AP$801),0) -> 0.31132222 | O4: =IFERROR(COUNTIFS(Loan_Data!$AK$2:$AK$801,$A4,Loan_Data!$AN$2:$AN$801,"Missed Payment")/(D4+G4),0) -> 0.23809524 | P4: =IFERROR(COUNTIFS(Loan_Data!$AK$2:$AK$801,$A4,Loan_Data!$AM$2:$AM$801,"Yes")/B4,0) -> 0.15555556
A5: TOTAL / OVERALL | B5: =SUM(B2:B4) -> 800 | C5: =SUM(C2:C4) -> 1 | D5: =SUM(D2:D4) -> 480 | E5: =SUM(E2:E4) -> 134 | F5: =SUM(F2:F4) -> 126 | G5: =SUM(G2:G4) -> 60 | H5: =IFERROR((D5+G5)/B5,0) -> 0.675 | I5: =SUM(I2:I4) -> 416564462 | J5: =IFERROR(I5/(D5+G5),0) -> 771415.67 | K5: =AVERAGE(Loan_Data!$AI$2:$AI$801) -> 716.235 | L5: =AVERAGE(Loan_Data!$W$2:$W$801) -> 11.289838 | M5: =AVERAGE(Loan_Data!$AJ$2:$AJ$801) -> 0.43660625 | N5: =AVERAGE(Loan_Data!$AP$2:$AP$801) -> 0.24243875 | O5: =IFERROR(SUMPRODUCT(O2:O4,(D2:D4+G2:G4))/(D5+G5),0) -> 0.094444444 | P5: =COUNTIF(Loan_Data!$AM$2:$AM$801,"Yes")/COUNTA(Loan_Data!$AK$2:$AK$801) -> 0.145
